Workbook

Sheet Read Me
C2: = céllule modifiables avec input
C3: = céllule avec formules (pas d'input)
B5: Etape | C5: Description | D5: Tab | E5: Céllule
B6: 1. Etape | C6: Entrée nom de la société | D6: A. Comptes de résultats | E6: D2
B7: 2. Etape | C7: Entrée date des derniers comptes clôturés | D7: A. Comptes de résultats | E7: D3
B8: 3. Etape | C8: Enregistrement des comptes de résultats historiques | D8: A. Comptes de résultats | E8: B, D-G (Année en cours)
B9: 4. Etape | C9: Enregistrement des bilans historiques | D9: B. Bilan | E9: C-F (Année en cours)
B10: 5. Etape | C10: Planification des comptes de résultats prévisionnels | D10: A. Comptes de résultats | E10: I-M (PLAN annuel)
B11: 6. Etape | C11: Calcul des Investissements de remplacement annuels estimés | D11: C. Bilan prévisionnel | E11: D8-D12
B12: 7. Etape | C12: Planification des investissements annuels futurs | D12: C. Bilan prévisionnel | E12: I19-M23
B13: 8. Etape | C13: Planification du capital circulant futur (Débiteurs, Stocks, Fournisseurs) | D13: C. Bilan prévisionnel | E13: I30-I32
B14: 9. Etape | C14: Détermination des liquidités minimum nécessaires à l'opérationnel | D14: C. Bilan prévisionnel | E14: I33
B15: 10. Etape | C15: Planification des autres positions futures du bilan | D15: B. Bilan | E15: H-L (PLAN annuel)
B16: 11. Etape | C16: Planification des Dividendes annuels futurs | D16: C. Bilan prévisionnel | E16: I43-M43

Sheet A. Comptes de résultats
B2: Nom de la société
B3: Date du dernier Exercice [tt.mm.jjjj] | D3: 44561
B5: Compte de résultat en TCHF
B6: Position | D6: Effectif-Année | I6: Prévisionnel-Année
D7: =DATE(YEAR(E7)-1,MONTH(E7),DAY(E7)) -> 43465 | E7: =DATE(YEAR(F7)-1,MONTH(F7),DAY(F7)) -> 43830 | F7: =DATE(YEAR(G7)-1,MONTH(G7),DAY(G7)) -> 44196 | G7: =D3 -> 44561 | I7: =DATE(YEAR(G7)+1,MONTH(G7),DAY(G7)) -> 44926 | J7: =DATE(YEAR(I7)+1,MONTH(I7),DAY(I7)) -> 45291 | K7: =DATE(YEAR(J7)+1,MONTH(J7),DAY(J7)) -> 45657 | L7: =DATE(YEAR(K7)+1,MONTH(K7),DAY(K7)) -> 46022 | M7: =DATE(YEAR(L7)+1,MONTH(L7),DAY(L7)) -> 46387
B8: Chiffre d'affaires net
B9: Charges matières
B10: Résultat brut | D10: =D8+D9 -> 0 | E10: =E8+E9 -> 0 | F10: =F8+F9 -> 0 | G10: =G8+G9 -> 0 | I10: =I8+I9 -> 0 | J10: =J8+J9 -> 0 | K10: =K8+K9 -> 0 | L10: =L8+L9 -> 0 | M10: =M8+M9 -> 0
B11: en % du chiffre d'affaires net | D11: =D10/D8 -> #DIV/0! | E11: =E10/E8 -> #DIV/0! | F11: =F10/F8 -> #DIV/0! | G11: =G10/G8 -> #DIV/0! | I11: =I10/I8 -> #DIV/0! | J11: =J10/J8 -> #DIV/0! | K11: =K10/K8 -> #DIV/0! | L11: =L10/L8 -> #DIV/0! | M11: =M10/M8 -> #DIV/0!
B13: Frais de personnel
B14: Charges matières
B15: Entretien, Réparation, Installations de remplacement
B16: Frais de transport et véhicules
B17: Assurances
B18: Frais d'électricité
B19: Frais administratifs et informatiques
B20: Frais de publicité
B21: Divers frais d'exploitation
B22: EBITDA | D22: =D10+SUM(D13:D21) -> 0 | E22: =E10+SUM(E13:E21) -> 0 | F22: =F10+SUM(F13:F21) -> 0 | G22: =G10+SUM(G13:G21) -> 0 | I22: =I10+SUM(I13:I21) -> 0 | J22: =J10+SUM(J13:J21) -> 0 | K22: =K10+SUM(K13:K21) -> 0 | L22: =L10+SUM(L13:L21) -> 0 | M22: =M10+SUM(M13:M21) -> 0
B23: en % du chiffre d'affaires net | D23: =D22/D8 -> #DIV/0! | E23: =E22/E8 -> #DIV/0! | F23: =F22/F8 -> #DIV/0! | G23: =G22/G8 -> #DIV/0! | I23: =I22/I8 -> #DIV/0! | J23: =J22/J8 -> #DIV/0! | K23: =K22/K8 -> #DIV/0! | L23: =L22/L8 -> #DIV/0! | M23: =M22/M8 -> #DIV/0!
B25: Amortissement
B26: EBIT | D26: =D22+D25 -> 0 | E26: =E22+E25 -> 0 | F26: =F22+F25 -> 0 | G26: =G22+G25 -> 0 | I26: =I22+I25 -> 0 | J26: =J22+J25 -> 0 | K26: =K22+K25 -> 0 | L26: =L22+L25 -> 0 | M26: =M22+M25 -> 0
B27: en % du chiffre d'affaires net | D27: =D26/D8 -> #DIV/0! | E27: =E26/E8 -> #DIV/0! | F27: =F26/F8 -> #DIV/0! | G27: =G26/G8 -> #DIV/0! | I27: =I26/I8 -> #DIV/0! | J27: =J26/J8 -> #DIV/0! | K27: =K26/K8 -> #DIV/0! | L27: =L26/L8 -> #DIV/0! | M27: =M26/M8 -> #DIV/0!
B29: Résultat financier
B30: Résultat exceptionnel
B31: Résultat immobilier
B32: Impôts
B33: en % de l'EBIT | D33: =-D32/D26 -> #DIV/0! | E33: =-E32/E26 -> #DIV/0! | F33: =-F32/F26 -> #DIV/0! | G33: =-G32/G26 -> #DIV/0! | I33: =-I32/I26 -> #DIV/0! | J33: =-J32/J26 -> #DIV/0! | K33: =-K32/K26 -> #DIV/0! | L33: =-L32/L26 -> #DIV/0! | M33: =-M32/M26 -> #DIV/0!
B34: Bénéfice | D34: =D26+SUM(D29:D32) -> 0 | E34: =E26+SUM(E29:E32) -> 0 | F34: =F26+SUM(F29:F32) -> 0 | G34: =G26+SUM(G29:G32) -> 0 | I34: =I26+SUM(I29:I32) -> 0 | J34: =J26+SUM(J29:J32) -> 0 | K34: =K26+SUM(K29:K32) -> 0 | L34: =L26+SUM(L29:L32) -> 0 | M34: =M26+SUM(M29:M32) -> 0
B35: en % du chiffre d'affaires net | D35: =D34/D8 -> #DIV/0! | E35: =E34/E8 -> #DIV/0! | F35: =F34/F8 -> #DIV/0! | G35: =G34/G8 -> #DIV/0! | I35: =I34/I8 -> #DIV/0! | J35: =J34/J8 -> #DIV/0! | K35: =K34/K8 -> #DIV/0! | L35: =L34/L8 -> #DIV/0! | M35: =M34/M8 -> #DIV/0!

Sheet B. Bilan
B2: Nom de la société | C2: ='A. Comptes de résultats'!D2 -> 0
B3: Date du dernier Exercice [tt.mm.jjjj] | C3: ='A. Comptes de résultats'!D3 -> 44561
B5: Bilan en TCHF
B6: Position | C6: Effectif-Année | H6: Prévisionnel-Année
C7: ='A. Comptes de résultats'!D7 -> 43465 | D7: ='A. Comptes de résultats'!E7 -> 43830 | E7: ='A. Comptes de résultats'!F7 -> 44196 | F7: ='A. Comptes de résultats'!G7 -> 44561 | H7: ='A. Comptes de résultats'!I7 -> 44926 | I7: ='A. Comptes de résultats'!J7 -> 45291 | J7: ='A. Comptes de résultats'!K7 -> 45657 | K7: ='A. Comptes de résultats'!L7 -> 46022 | L7: ='A. Comptes de résultats'!M7 -> 46387
B8: Liquidités | H8: 0 | I8: 0 | J8: 0 | K8: 0 | L8: 0
B9: Betriebsnotwendige Liquidite Mittel | H9: ='[1]C. Bilanzplanung'!$I$33 -> 0 | I9: ='[1]C. Bilanzplanung'!$I$33 -> 0 | J9: ='[1]C. Bilanzplanung'!$I$33 -> 0 | K9: ='[1]C. Bilanzplanung'!$I$33 -> 0 | L9: ='[1]C. Bilanzplanung'!$I$33 -> 0
B10: Überschüssige Liquide Mittel nach Dividende | H10: ='[1]C. Bilanzplanung'!I45 -> 0 | I10: ='[1]C. Bilanzplanung'!J45 -> 0 | J10: ='[1]C. Bilanzplanung'!K45 -> 0 | K10: ='[1]C. Bilanzplanung'!L45 -> 0 | L10: ='[1]C. Bilanzplanung'!M45 -> 0
B11: Débiteurs | H11: ='[1]C. Bilanzplanung'!$I$30*'[1]A. Erfolgsrechnung'!I8/360 -> 0 | I11: ='[1]C. Bilanzplanung'!$I$30*'[1]A. Erfolgsrechnung'!J8/360 -> 0 | J11: ='[1]C. Bilanzplanung'!$I$30*'[1]A. Erfolgsrechnung'!K8/360 -> 0 | K11: ='[1]C. Bilanzplanung'!$I$30*'[1]A. Erfolgsrechnung'!L8/360 -> 0 | L11: ='[1]C. Bilanzplanung'!$I$30*'[1]A. Erfolgsrechnung'!M8/360 -> 0
B12: Provision sur débiteurs douteux
B13: Stocks | H13: ='[1]C. Bilanzplanung'!$I$31*-'[1]A. Erfolgsrechnung'!I9/360 -> 0 | I13: ='[1]C. Bilanzplanung'!$I$31*-'[1]A. Erfolgsrechnung'!J9/360 -> 0 | J13: ='[1]C. Bilanzplanung'!$I$31*-'[1]A. Erfolgsrechnung'!K9/360 -> 0 | K13: ='[1]C. Bilanzplanung'!$I$31*-'[1]A. Erfolgsrechnung'!L9/360 -> 0 | L13: ='[1]C. Bilanzplanung'!$I$31*-'[1]A. Erfolgsrechnung'!M9/360 -> 0
B14: Travaux en cours
B15: Actifs transitoires
B16: CC / Prêt intercompany
B17: Divers actifs circulants
B18: Actifs circulants | C18: =SUM(C11,C13:C17)+C12+C8 -> 0 | D18: =SUM(D11,D13:D17)+D12+D8 -> 0 | E18: =SUM(E11,E13:E17)+E12+E8 -> 0 | F18: =SUM(F11,F13:F17)+F12+F8 -> 0 | H18: =SUM(H11,H13:H17)+H12+H8 -> 0 | I18: =SUM(I11,I13:I17)+I12+I8 -> 0 | J18: =SUM(J11,J13:J17)+J12+J8 -> 0 | K18: =SUM(K11,K13:K17)+K12+K8 -> 0 | L18: =SUM(L11,L13:L17)+L12+L8 -> 0
B21: Immobilisations corporelles
B22: Immobilisations financières
B23: Immobilisations incorporelles
B24: Actifs immobilisés | C24: =SUM(C20:C23) -> 0 | D24: =SUM(D20:D23) -> 0 | E24: =SUM(E20:E23) -> 0 | F24: =SUM(F20:F23) -> 0 | H24: 0 | I24: 0 | J24: 0 | K24: 0 | L24: 0
B25: ACTIFS | C25: =SUM(C18,C24) -> 0 | D25: =SUM(D18,D24) -> 0 | E25: =SUM(E18,E24) -> 0 | F25: =SUM(F18,F24) -> 0 | H25: =H18+H24 -> 0 | I25: =I18+I24 -> 0 | J25: =J18+J24 -> 0 | K25: =K18+K24 -> 0 | L25: =L18+L24 -> 0
B27: Fournisseurs | H27: ='[1]C. Bilanzplanung'!$I$32*-'[1]A. Erfolgsrechnung'!I9/360 -> 0 | I27: ='[1]C. Bilanzplanung'!$I$32*-'[1]A. Erfolgsrechnung'!J9/360 -> 0 | J27: ='[1]C. Bilanzplanung'!$I$32*-'[1]A. Erfolgsrechnung'!K9/360 -> 0 | K27: ='[1]C. Bilanzplanung'!$I$32*-'[1]A. Erfolgsrechnung'!L9/360 -> 0 | L27: ='[1]C. Bilanzplanung'!$I$32*-'[1]A. Erfolgsrechnung'!M9/360 -> 0
B28: Passifs transitoires
B29: Avances clients
B30: Banques à court terme
B31: Divers fds étrangers à court terme
B32: Fonds étrangers à court terme | C32: =SUM(C27:C31) -> 0 | D32: =SUM(D27:D31) -> 0 | E32: =SUM(E27:E31) -> 0 | F32: =SUM(F27:F31) -> 0 | H32: =SUM(H27:H31) -> 0 | I32: =SUM(I27:I31) -> 0 | J32: =SUM(J27:J31) -> 0 | K32: =SUM(K27:K31) -> 0 | L32: =SUM(L27:L31) -> 0
B34: Provisions
B35: Banques à long terme
B36: Hypothèques
B37: CC / Prêt intercompany
B38: Divers fds étrangers à long terme
B39: Fonds étrangers à long terme | C39: =SUM(C34:C38) -> 0 | D39: =SUM(D34:D38) -> 0 | E39: =SUM(E34:E38) -> 0 | F39: =SUM(F34:F38) -> 0 | H39: =SUM(H34:H38) -> 0 | I39: =SUM(I34:I38) -> 0 | J39: =SUM(J34:J38) -> 0 | K39: =SUM(K34:K38) -> 0 | L39: =SUM(L34:L38) -> 0
B41: Manque de financement | H41: =IF(H48+H39+H32<H24+SUM(H11:H17)+H9,-(H48+H39+H32)+H24+SUM(H11:H17)+H9,0) -> 0 | I41: =IF(I48+I39+I32<I24+SUM(I11:I17)+I9,-(I48+I39+I32)+I24+SUM(I11:I17)+I9,0) -> 0 | J41: =IF(J48+J39+J32<J24+SUM(J11:J17)+J9,-(J48+J39+J32)+J24+SUM(J11:J17)+J9,0) -> 0 | K41: =IF(K48+K39+K32<K24+SUM(K11:K17)+K9,-(K48+K39+K32)+K24+SUM(K11:K17)+K9,0) -> 0 | L41: =IF(L48+L39+L32<L24+SUM(L11:L17)+L9,-(L48+L39+L32)+L24+SUM(L11:L17)+L9,0) -> 0
B43: Capital en actions | H43: =F43 -> 0 | I43: =H43 -> 0 | J43: =I43 -> 0 | K43: =J43 -> 0 | L43: =K43 -> 0
B44: Réserves légales | H44: =F44 -> 0 | I44: =H44 -> 0 | J44: =I44 -> 0 | K44: =J44 -> 0 | L44: =K44 -> 0
B45: Réserves libres / Report | H45: =F45+F46+'[1]A. Erfolgsrechnung'!I34-'[1]C. Bilanzplanung'!I44 -> 0 | I45: =H45+'[1]A. Erfolgsrechnung'!J34-'[1]C. Bilanzplanung'!J44 -> 0 | J45: =I45+'[1]A. Erfolgsrechnung'!K34-'[1]C. Bilanzplanung'!K44 -> 0 | K45: =J45+'[1]A. Erfolgsrechnung'!L34-'[1]C. Bilanzplanung'!L44 -> 0 | L45: =K45+'[1]A. Erfolgsrechnung'!M34-'[1]C. Bilanzplanung'!M44 -> 0
B46: Bénéfice net | C46: ='[1]A. Erfolgsrechnung'!D34 -> 0 | D46: ='[1]A. Erfolgsrechnung'!E34 -> 0 | E46: ='[1]A. Erfolgsrechnung'!F34 -> 0 | F46: ='[1]A. Erfolgsrechnung'!G34 -> 0
B47: Dividende
B48: Fonds propres | C48: =SUM(C43:C46) -> 0 | D48: =SUM(D43:D46) -> 0 | E48: =SUM(E43:E46) -> 0 | F48: =SUM(F43:F46) -> 0 | H48: =H43+H44+H45 -> 0 | I48: =I43+I44+I45 -> 0 | J48: =J43+J44+J45+J46 -> 0 | K48: =K43+K44+K45+K46 -> 0 | L48: =L43+L44+L45+L46 -> 0
...

Sheet C. Bilan prévisionnel
B2: Nom de la société | D2: ='A. Comptes de résultats'!D2 -> 0
B3: Date du dernier Exercice [tt.mm.jjjj] | D3: ='A. Comptes de résultats'!D3 -> 44561
B5: Immobilisations corporelles TCHF
B6: Position | D6: Valeur d'acquisition | E6: Ammortissements p.a. | F6: Investissement de rempl. p.a.
B8: Véhicules | E8: 0.2 | F8: =D8*E8 -> 0
B9: Informatique | E9: 0.2 | F9: =D9*E9 -> 0
B10: Machines | E10: 0.1 | F10: =D10*E10 -> 0
B11: Mobilier | E11: 0.1 | F11: =D11*E11 -> 0
B12: Immobilier (propre utilisation) | E12: 0.03 | F12: =D12*E12 -> 0
F13: =D13*E13 -> 0
B14: Total | D14: =SUM(D8:D13) -> 0 | F14: =SUM(F8:F13) -> 0
B16: Plan d'investissement TCHF
B17: Position | D17: Effectif-Année | I17: Prévisionnel-Année
D18: ='B. Bilan'!C7 -> 43465 | E18: ='B. Bilan'!D7 -> 43830 | F18: ='B. Bilan'!E7 -> 44196 | G18: ='B. Bilan'!F7 -> 44561 | I18: ='A. Comptes de résultats'!I7 -> 44926 | J18: ='A. Comptes de résultats'!J7 -> 45291 | K18: ='A. Comptes de résultats'!K7 -> 45657 | L18: ='A. Comptes de résultats'!L7 -> 46022 | M18: ='A. Comptes de résultats'!M7 -> 46387
B19: Véhicules
B20: Informatique
B21: Machines
B22: Mobilier
B23: Immobilier (propre utilisation)
B25: Total | D25: ='[1]B. Bilanz'!D24-'[1]B. Bilanz'!C24-'[1]A. Erfolgsrechnung'!E25 -> 0 | E25: ='[1]B. Bilanz'!E24-'[1]B. Bilanz'!D24-'[1]A. Erfolgsrechnung'!F25 -> 0 | F25: ='[1]B. Bilanz'!F24-'[1]B. Bilanz'!E24-'[1]A. Erfolgsrechnung'!G25 -> 0 | G25: ='[1]B. Bilanz'!F24-'[1]B. Bilanz'!E24-'[1]A. Erfolgsrechnung'!I25 -> 0 | I25: =SUM(I19:I24) -> 0 | J25: =SUM(J19:J24) -> 0 | K25: =SUM(K19:K24) -> 0 | L25: =SUM(L19:L24) -> 0 | M25: =SUM(M19:M24) -> 0
B27: Bilan prévisionnel TCHF
B28: Position | D28: Effectif-Année | I28: Prév.-Année
D29: =D18 -> 43465 | E29: =E18 -> 43830 | F29: =F18 -> 44196 | G29: =G18 -> 44561
B30: Rotation des débiteurs | E30: ='[1]B. Bilanz'!D11/'[1]A. Erfolgsrechnung'!E8*360 -> #DIV/0! | F30: ='[1]B. Bilanz'!E11/'[1]A. Erfolgsrechnung'!F8*360 -> #DIV/0! | G30: ='[1]B. Bilanz'!F11/'[1]A. Erfolgsrechnung'!G8*360 -> #DIV/0! | H30: ='[1]B. Bilanz'!G11/'[1]A. Erfolgsrechnung'!H8*360 -> #DIV/0!
B31: Rotation des stocks | E31: ='[1]B. Bilanz'!D13/-'[1]A. Erfolgsrechnung'!E9*360 -> #DIV/0! | F31: ='[1]B. Bilanz'!E13/-'[1]A. Erfolgsrechnung'!F9*360 -> #DIV/0! | G31: ='[1]B. Bilanz'!F13/-'[1]A. Erfolgsrechnung'!G9*360 -> #DIV/0! | H31: ='[1]B. Bilanz'!G13/-'[1]A. Erfolgsrechnung'!H9*360 -> #DIV/0!
B32: Rotation des fournisseurs | E32: ='[1]B. Bilanz'!D27/-'[1]A. Erfolgsrechnung'!E9*360 -> #DIV/0! | F32: ='[1]B. Bilanz'!E27/-'[1]A. Erfolgsrechnung'!F9*360 -> #DIV/0! | G32: ='[1]B. Bilanz'!F27/-'[1]A. Erfolgsrechnung'!G9*360 -> #DIV/0! | H32: ='[1]B. Bilanz'!G27/-'[1]A. Erfolgsrechnung'!H9*360 -> #DIV/0!
B33: Liquidités nécessaires à l'exploitation
B35: Plan de versements de Dividende TCHF
B36: Position | I36: Prévisionnel-Année
I37: ='A. Comptes de résultats'!I7 -> 44926 | J37: ='A. Comptes de résultats'!J7 -> 45291 | K37: ='A. Comptes de résultats'!K7 -> 45657 | L37: ='A. Comptes de résultats'!L7 -> 46022 | M37: ='A. Comptes de résultats'!M7 -> 46387
B38: Total Aktiven (exkl. Überschüssiger Cash & Dividende) | I38: ='B. Bilan'!H9+SUM('B. Bilan'!H11:H17)+'B. Bilan'!H24 -> 0 | J38: ='B. Bilan'!I9+SUM('B. Bilan'!I11:I17)+'B. Bilan'!I24 -> 0 | K38: ='B. Bilan'!J9+SUM('B. Bilan'!J11:J17)+'B. Bilan'!J24 -> 0 | L38: ='B. Bilan'!K9+SUM('B. Bilan'!K11:K17)+'B. Bilan'!K24 -> 0 | M38: ='B. Bilan'!L9+SUM('B. Bilan'!L11:L17)+'B. Bilan'!L24 -> 0
B39: Total Passiven (exkl. Finanzierungslücke & Dividende) | I39: ='B. Bilan'!H32+'B. Bilan'!H39+'B. Bilan'!H43+'B. Bilan'!H44+'A. Comptes de résultats'!I34+SUM('B. Bilan'!F45:F46) -> 0 | J39: ='B. Bilan'!I32+'B. Bilan'!I39+'B. Bilan'!I43+'B. Bilan'!I44+'A. Comptes de résultats'!J34+'B. Bilan'!H45 -> 0 | K39: ='B. Bilan'!J32+'B. Bilan'!J39+'B. Bilan'!J43+'B. Bilan'!J44+'A. Comptes de résultats'!K34+'B. Bilan'!I45 -> 0 | L39: ='B. Bilan'!K32+'B. Bilan'!K39+'B. Bilan'!K43+'B. Bilan'!K44+'A. Comptes de résultats'!L34+'B. Bilan'!J45 -> 0 | M39: ='B. Bilan'!L32+'B. Bilan'!L39+'B. Bilan'!L43+'B. Bilan'!L44+'A. Comptes de résultats'!M34+'B. Bilan'!K45 -> 0
B40: Überschüssiger Cash vor Dividende | I40: =IF(I39>I38, I39-I38,0) -> 0 | J40: =IF(J39>J38, J39-J38,0) -> 0 | K40: =IF(K39>K38, K39-K38,0) -> 0 | L40: =IF(L39>L38, L39-L38,0) -> 0 | M40: =IF(M39>M38, M39-M38,0) -> 0
B41: Dividende maximum - prise en considération des réserves distribuables | I41: =IF('[1]B. Bilanz'!F45+'[1]B. Bilanz'!F46+'[1]A. Erfolgsrechnung'!I34>0,'[1]B. Bilanz'!F45+'[1]B. Bilanz'!F46+'[1]A. Erfolgsrechnung'!I34,0) -> 0 | J41: =IF('[1]B. Bilanz'!H45+'[1]A. Erfolgsrechnung'!J34>0,'[1]B. Bilanz'!H45+'[1]A. Erfolgsrechnung'!J34,0) -> 0 | K41: =IF('[1]B. Bilanz'!I45+'[1]A. Erfolgsrechnung'!K34>0,'[1]B. Bilanz'!I45+'[1]A. Erfolgsrechnung'!K34,0) -> 0 | L41: =IF('[1]B. Bilanz'!J45+'[1]A. Erfolgsrechnung'!L34>0,'[1]B. Bilanz'!J45+'[1]A. Erfolgsrechnung'!L34,0) -> 0 | M41: =IF('[1]B. Bilanz'!K45+'[1]A. Erfolgsrechnung'!M34>0,'[1]B. Bilanz'!K45+'[1]A. Erfolgsrechnung'!M34,0) -> 0
B42: Dividende maximum - prise en considération des liquidités | I42: =IF(MIN(I40:I41)>0,MIN(I40:I41),0) -> 0 | J42: =IF(MIN(J40:J41)>0,MIN(J40:J41),0) -> 0 | K42: =IF(MIN(K40:K41)>0,MIN(K40:K41),0) -> 0 | L42: =IF(MIN(L40:L41)>0,MIN(L40:L41),0) -> 0 | M42: =IF(MIN(M40:M41)>0,MIN(M40:M41),0) -> 0
B43: Plan de versements de Dividende
B44: Dividende effectif | I44: =IF(I43<I42, I43,I42) -> 0 | J44: =IF(J43<J42, J43,J42) -> 0 | K44: =IF(K43<K42, K43,K42) -> 0 | L44: =IF(L43<L42, L43,L42) -> 0 | M44: =IF(M43<M42, M43,M42) -> 0
B45: Cash excédentaire après Dividende | I45: =IF(I43<I40,I40-I43,0) -> 0 | J45: =IF(J43<J40,J40-J43,0) -> 0 | K45: =IF(K43<K40,K40-K43,0) -> 0 | L45: =IF(L43<L40,L40-L43,0) -> 0 | M45: =IF(M43<M40,M40-M43,0) -> 0

Sheet D. Tableau de flux de fonds
B2: Nom de la société | C2: ='A. Comptes de résultats'!D2 -> 0
B3: Date du dernier Exercice [tt.mm.jjjj] | C3: ='A. Comptes de résultats'!D3 -> 44561
B5: Tableau de flux de fonds
B6: Position | C6: Effectif-Année | I6: Prévisionnel-Année
C7: =YEAR('A. Comptes de résultats'!E7) -> 2019 | E7: =YEAR('A. Comptes de résultats'!F7) -> 2020 | G7: =YEAR('A. Comptes de résultats'!G7) -> 2021 | I7: =YEAR('A. Comptes de résultats'!I7) -> 2022 | J7: =YEAR('A. Comptes de résultats'!J7) -> 2023 | K7: =YEAR('A. Comptes de résultats'!K7) -> 2024 | L7: =YEAR('A. Comptes de résultats'!L7) -> 2025 | M7: =YEAR('A. Comptes de résultats'!M7) -> 2026
B8: Bénéfice net | C8: ='A. Comptes de résultats'!E34 -> 0 | E8: ='A. Comptes de résultats'!F34 -> 0 | G8: ='A. Comptes de résultats'!G34 -> 0 | I8: ='A. Comptes de résultats'!I34 -> 0 | J8: ='A. Comptes de résultats'!J34 -> 0 | K8: ='A. Comptes de résultats'!K34 -> 0 | L8: ='A. Comptes de résultats'!L34 -> 0 | M8: ='A. Comptes de résultats'!M34 -> 0
B9: + Amortissements | C9: =-'A. Comptes de résultats'!E25 -> 0 | E9: =-'A. Comptes de résultats'!F25 -> 0 | G9: =-'A. Comptes de résultats'!G25 -> 0 | I9: =-'A. Comptes de résultats'!I25 -> 0 | J9: =-'A. Comptes de résultats'!J25 -> 0 | K9: =-'A. Comptes de résultats'!K25 -> 0 | L9: =-'A. Comptes de résultats'!L25 -> 0 | M9: =-'A. Comptes de résultats'!M25 -> 0
B10: + Résultats financiers | C10: =-'A. Comptes de résultats'!E29 -> 0 | E10: =-'A. Comptes de résultats'!F29 -> 0 | G10: =-'A. Comptes de résultats'!G29 -> 0 | I10: =-'A. Comptes de résultats'!I29 -> 0 | J10: =-'A. Comptes de résultats'!J29 -> 0 | K10: =-'A. Comptes de résultats'!K29 -> 0 | L10: =-'A. Comptes de résultats'!L29 -> 0 | M10: =-'A. Comptes de résultats'!M29 -> 0
B11: +/- Debiteurs | C11: ='B. Bilan'!C11-'B. Bilan'!D11 -> 0 | E11: ='B. Bilan'!D11-'B. Bilan'!E11 -> 0 | G11: ='B. Bilan'!E11-'B. Bilan'!F11 -> 0 | I11: ='B. Bilan'!F11-'B. Bilan'!H11 -> 0 | J11: ='B. Bilan'!H11-'B. Bilan'!I11 -> 0 | K11: ='B. Bilan'!I11-'B. Bilan'!J11 -> 0 | L11: ='B. Bilan'!J11-'B. Bilan'!K11 -> 0 | M11: ='B. Bilan'!K11-'B. Bilan'!L11 -> 0
B12: +/- Provisions sur débiteurs douteux | C12: ='B. Bilan'!C12-'B. Bilan'!D12 -> 0 | E12: ='B. Bilan'!D12-'B. Bilan'!E12 -> 0 | G12: ='B. Bilan'!E12-'B. Bilan'!F12 -> 0 | I12: ='B. Bilan'!F12-'B. Bilan'!H12 -> 0 | J12: ='B. Bilan'!H12-'B. Bilan'!I12 -> 0 | K12: ='B. Bilan'!I12-'B. Bilan'!J12 -> 0 | L12: ='B. Bilan'!J12-'B. Bilan'!K12 -> 0 | M12: ='B. Bilan'!K12-'B. Bilan'!L12 -> 0
B13: +/- Stocks | C13: ='B. Bilan'!C13-'B. Bilan'!D13 -> 0 | E13: ='B. Bilan'!D13-'B. Bilan'!E13 -> 0 | G13: ='B. Bilan'!E13-'B. Bilan'!F13 -> 0 | I13: ='B. Bilan'!F13-'B. Bilan'!H13 -> 0 | J13: ='B. Bilan'!H13-'B. Bilan'!I13 -> 0 | K13: ='B. Bilan'!I13-'B. Bilan'!J13 -> 0 | L13: ='B. Bilan'!J13-'B. Bilan'!K13 -> 0 | M13: ='B. Bilan'!K13-'B. Bilan'!L13 -> 0
B14: +/- Travaux en cours | C14: ='B. Bilan'!C14-'B. Bilan'!D14 -> 0 | E14: ='B. Bilan'!D14-'B. Bilan'!E14 -> 0 | G14: ='B. Bilan'!E14-'B. Bilan'!F14 -> 0 | I14: ='B. Bilan'!F14-'B. Bilan'!H14 -> 0 | J14: ='B. Bilan'!H14-'B. Bilan'!I14 -> 0 | K14: ='B. Bilan'!I14-'B. Bilan'!J14 -> 0 | L14: ='B. Bilan'!J14-'B. Bilan'!K14 -> 0 | M14: ='B. Bilan'!K14-'B. Bilan'!L14 -> 0
B15: +/- Actifs transitoires | C15: ='B. Bilan'!C15-'B. Bilan'!D15 -> 0 | E15: ='B. Bilan'!D15-'B. Bilan'!E15 -> 0 | G15: ='B. Bilan'!E15-'B. Bilan'!F15 -> 0 | I15: ='B. Bilan'!F15-'B. Bilan'!H15 -> 0 | J15: ='B. Bilan'!H15-'B. Bilan'!I15 -> 0 | K15: ='B. Bilan'!I15-'B. Bilan'!J15 -> 0 | L15: ='B. Bilan'!J15-'B. Bilan'!K15 -> 0 | M15: ='B. Bilan'!K15-'B. Bilan'!L15 -> 0
B16: +/- Divers actifs circulants | C16: ='B. Bilan'!C17-'B. Bilan'!D17 -> 0 | E16: ='B. Bilan'!D17-'B. Bilan'!E17 -> 0 | G16: ='B. Bilan'!E17-'B. Bilan'!F17 -> 0 | I16: ='B. Bilan'!F17-'B. Bilan'!H17 -> 0 | J16: ='B. Bilan'!H17-'B. Bilan'!I17 -> 0 | K16: ='B. Bilan'!I17-'B. Bilan'!J17 -> 0 | L16: ='B. Bilan'!J17-'B. Bilan'!K17 -> 0 | M16: ='B. Bilan'!K17-'B. Bilan'!L17 -> 0
B17: +/- Fournisseurs | C17: ='B. Bilan'!D27-'B. Bilan'!C27 -> 0 | E17: ='B. Bilan'!E27-'B. Bilan'!D27 -> 0 | G17: ='B. Bilan'!F27-'B. Bilan'!E27 -> 0 | I17: ='B. Bilan'!H27-'B. Bilan'!F27 -> 0 | J17: ='B. Bilan'!I27-'B. Bilan'!H27 -> 0 | K17: ='B. Bilan'!J27-'B. Bilan'!I27 -> 0 | L17: ='B. Bilan'!K27-'B. Bilan'!J27 -> 0 | M17: ='B. Bilan'!L27-'B. Bilan'!K27 -> 0
B18: +/- Passifs transitoires | C18: ='B. Bilan'!D28-'B. Bilan'!C28 -> 0 | E18: ='B. Bilan'!E28-'B. Bilan'!D28 -> 0 | G18: ='B. Bilan'!F28-'B. Bilan'!E28 -> 0 | I18: ='B. Bilan'!H28-'B. Bilan'!F28 -> 0 | J18: ='B. Bilan'!I28-'B. Bilan'!H28 -> 0 | K18: ='B. Bilan'!J28-'B. Bilan'!I28 -> 0 | L18: ='B. Bilan'!K28-'B. Bilan'!J28 -> 0 | M18: ='B. Bilan'!L28-'B. Bilan'!K28 -> 0
B19: +/- Avances clients | C19: ='B. Bilan'!D29-'B. Bilan'!C29 -> 0 | E19: ='B. Bilan'!E29-'B. Bilan'!D29 -> 0 | G19: ='B. Bilan'!F29-'B. Bilan'!E29 -> 0 | I19: ='B. Bilan'!H29-'B. Bilan'!F29 -> 0 | J19: ='B. Bilan'!I29-'B. Bilan'!H29 -> 0 | K19: ='B. Bilan'!J29-'B. Bilan'!I29 -> 0 | L19: ='B. Bilan'!K29-'B. Bilan'!J29 -> 0 | M19: ='B. Bilan'!L29-'B. Bilan'!K29 -> 0
B20: +/- Divers fonds étrangers à court terme | C20: ='B. Bilan'!D31-'B. Bilan'!C31 -> 0 | E20: ='B. Bilan'!E31-'B. Bilan'!D31 -> 0 | G20: ='B. Bilan'!F31-'B. Bilan'!E31 -> 0 | I20: ='B. Bilan'!H31-'B. Bilan'!F31 -> 0 | J20: ='B. Bilan'!I31-'B. Bilan'!H31 -> 0 | K20: ='B. Bilan'!J31-'B. Bilan'!I31 -> 0 | L20: ='B. Bilan'!K31-'B. Bilan'!J31 -> 0 | M20: ='B. Bilan'!L31-'B. Bilan'!K31 -> 0
B21: + Modification de l’actif courant net | C21: =SUM(C11:C20) -> 0 | E21: =SUM(E11:E20) -> 0 | G21: =SUM(G11:G20) -> 0 | I21: =SUM(I11:I20) -> 0 | J21: =SUM(J11:J20) -> 0 | K21: =SUM(K11:K20) -> 0 | L21: =SUM(L11:L20) -> 0 | M21: =SUM(M11:M20) -> 0
B22: +/- Provisions | C22: ='B. Bilan'!D34-'B. Bilan'!C34 -> 0 | E22: ='B. Bilan'!E34-'B. Bilan'!D34 -> 0 | G22: ='B. Bilan'!F34-'B. Bilan'!E34 -> 0 | I22: ='B. Bilan'!H34-'B. Bilan'!F34 -> 0 | J22: ='B. Bilan'!I34-'B. Bilan'!H34 -> 0 | K22: ='B. Bilan'!J34-'B. Bilan'!I34 -> 0 | L22: ='B. Bilan'!K34-'B. Bilan'!J34 -> 0 | M22: ='B. Bilan'!L34-'B. Bilan'!K34 -> 0
B23: Cash flow opérationnel | C23: =C8+C9+C10+C21+C22 -> 0 | E23: =E8+E9+E10+E21+E22 -> 0 | G23: =G8+G9+G10+G21+G22 -> 0 | I23: =I8+I9+I10+I21+I22 -> 0 | J23: =J8+J9+J10+J21+J22 -> 0 | K23: =K8+K9+K10+K21+K22 -> 0 | L23: =L8+L9+L10+L21+L22 -> 0 | M23: =M8+M9+M10+M21+M22 -> 0
B25: Investissements | C25: ='B. Bilan'!D24-'B. Bilan'!C24-'A. Comptes de résultats'!E25 -> 0 | E25: ='B. Bilan'!E24-'B. Bilan'!D24-'A. Comptes de résultats'!F25 -> 0 | G25: ='B. Bilan'!F24-'B. Bilan'!E24-'A. Comptes de résultats'!G25 -> 0 | I25: ='B. Bilan'!H24-'B. Bilan'!F24-'A. Comptes de résultats'!I25 -> 0 | J25: ='B. Bilan'!I24-'B. Bilan'!H24-'A. Comptes de résultats'!J25 -> 0 | K25: ='B. Bilan'!J24-'B. Bilan'!I24-'A. Comptes de résultats'!K25 -> 0 | L25: ='B. Bilan'!K24-'B. Bilan'!J24-'A. Comptes de résultats'!L25 -> 0 | M25: ='B. Bilan'!L24-'B. Bilan'!K24-'A. Comptes de résultats'!M25 -> 0
B26: Cash flow des investissements | C26: =-C25 -> 0 | E26: =-E25 -> 0 | G26: =-G25 -> 0 | I26: =-I25 -> 0 | J26: =-J25 -> 0 | K26: =-K25 -> 0 | L26: =-L25 -> 0 | M26: =-M25 -> 0
B28: FCF | C28: =C23+C26 -> 0 | E28: =E23+E26 -> 0 | G28: =G23+G26 -> 0 | I28: =I23+I26 -> 0 | J28: =J23+J26 -> 0 | K28: =K23+K26 -> 0 | L28: =L23+L26 -> 0 | M28: =M23+M26 -> 0
B29: - Résultats financiers | C29: =-C10 -> 0 | E29: =-E10 -> 0 | G29: =-G10 -> 0 | I29: =-I10 -> 0 | J29: =-J10 -> 0 | K29: =-K10 -> 0 | L29: =-L10 -> 0 | M29: =-M10 -> 0
B30: +/- CC / Prêt Intercompany débiteur | C30: ='B. Bilan'!C16-'B. Bilan'!D16 -> 0 | E30: ='B. Bilan'!D16-'B. Bilan'!E16 -> 0 | G30: ='B. Bilan'!E16-'B. Bilan'!F16 -> 0 | I30: ='B. Bilan'!F16-'B. Bilan'!H16 -> 0 | J30: ='B. Bilan'!H16-'B. Bilan'!I16 -> 0 | K30: ='B. Bilan'!I16-'B. Bilan'!J16 -> 0 | L30: ='B. Bilan'!J16-'B. Bilan'!K16 -> 0 | M30: ='B. Bilan'!K16-'B. Bilan'!L16 -> 0
B31: +/- CC / Prêt Intercompany créditeur | C31: ='B. Bilan'!D37-'B. Bilan'!C37 -> 0 | E31: ='B. Bilan'!E37-'B. Bilan'!D37 -> 0 | G31: ='B. Bilan'!F37-'B. Bilan'!E37 -> 0 | I31: ='B. Bilan'!H37-'B. Bilan'!F37 -> 0 | J31: ='B. Bilan'!I37-'B. Bilan'!H37 -> 0 | K31: ='B. Bilan'!J37-'B. Bilan'!I37 -> 0 | L31: ='B. Bilan'!K37-'B. Bilan'!J37 -> 0 | M31: ='B. Bilan'!L37-'B. Bilan'!K37 -> 0
B32: +/- Banques à court terme | C32: ='B. Bilan'!D30-'B. Bilan'!C30 -> 0 | E32: ='B. Bilan'!E30-'B. Bilan'!D30 -> 0 | G32: ='B. Bilan'!F30-'B. Bilan'!E30 -> 0 | I32: ='B. Bilan'!H30-'B. Bilan'!F30 -> 0 | J32: ='B. Bilan'!I30-'B. Bilan'!H30 -> 0 | K32: ='B. Bilan'!J30-'B. Bilan'!I30 -> 0 | L32: ='B. Bilan'!K30-'B. Bilan'!J30 -> 0 | M32: ='B. Bilan'!L30-'B. Bilan'!K30 -> 0
B33: +/- Banques à long terme | C33: ='B. Bilan'!D35-'B. Bilan'!C35 -> 0 | E33: ='B. Bilan'!E35-'B. Bilan'!D35 -> 0 | G33: ='B. Bilan'!F35-'B. Bilan'!E35 -> 0 | I33: ='B. Bilan'!H35-'B. Bilan'!F35 -> 0 | J33: ='B. Bilan'!I35-'B. Bilan'!H35 -> 0 | K33: ='B. Bilan'!J35-'B. Bilan'!I35 -> 0 | L33: ='B. Bilan'!K35-'B. Bilan'!J35 -> 0 | M33: ='B. Bilan'!L35-'B. Bilan'!K35 -> 0
B34: +/- Manque de financement | I34: ='B. Bilan'!H41-'B. Bilan'!F41 -> 0 | J34: ='B. Bilan'!I41-'B. Bilan'!H41 -> 0 | K34: ='B. Bilan'!J41-'B. Bilan'!I41 -> 0 | L34: ='B. Bilan'!K41-'B. Bilan'!J41 -> 0 | M34: ='B. Bilan'!L41-'B. Bilan'!K41 -> 0
B35: +/- Hypothèques | C35: ='B. Bilan'!D36-'B. Bilan'!C36 -> 0 | E35: ='B. Bilan'!E36-'B. Bilan'!D36 -> 0 | G35: ='B. Bilan'!F36-'B. Bilan'!E36 -> 0 | I35: ='B. Bilan'!H36-'B. Bilan'!F36 -> 0 | J35: ='B. Bilan'!I36-'B. Bilan'!H36 -> 0 | K35: ='B. Bilan'!J36-'B. Bilan'!I36 -> 0 | L35: ='B. Bilan'!K36-'B. Bilan'!J36 -> 0 | M35: ='B. Bilan'!L36-'B. Bilan'!K36 -> 0
B36: +/- Divers fonds étrangers à long terme | C36: ='B. Bilan'!D38-'B. Bilan'!C38 -> 0 | E36: ='B. Bilan'!E38-'B. Bilan'!D38 -> 0 | G36: ='B. Bilan'!F38-'B. Bilan'!E38 -> 0 | I36: ='B. Bilan'!H38-'B. Bilan'!F38 -> 0 | J36: ='B. Bilan'!I38-'B. Bilan'!H38 -> 0 | K36: ='B. Bilan'!J38-'B. Bilan'!I38 -> 0 | L36: ='B. Bilan'!K38-'B. Bilan'!J38 -> 0 | M36: ='B. Bilan'!L38-'B. Bilan'!K38 -> 0
B37: +/- Capital en actions | C37: ='B. Bilan'!D43-'B. Bilan'!C43 -> 0 | E37: ='B. Bilan'!E43-'B. Bilan'!D43 -> 0 | G37: ='B. Bilan'!F43-'B. Bilan'!E43 -> 0 | I37: ='B. Bilan'!H43-'B. Bilan'!F43 -> 0 | J37: ='B. Bilan'!I43-'B. Bilan'!H43 -> 0 | K37: ='B. Bilan'!J43-'B. Bilan'!I43 -> 0 | L37: ='B. Bilan'!K43-'B. Bilan'!J43 -> 0 | M37: ='B. Bilan'!L43-'B. Bilan'!K43 -> 0
B38: +/- Réserves légales | C38: ='B. Bilan'!D44-'B. Bilan'!C44 -> 0 | E38: ='B. Bilan'!E44-'B. Bilan'!D44 -> 0 | G38: ='B. Bilan'!F44-'B. Bilan'!E44 -> 0 | I38: ='B. Bilan'!H44-'B. Bilan'!F44 -> 0 | J38: ='B. Bilan'!I44-'B. Bilan'!H44 -> 0 | K38: ='B. Bilan'!J44-'B. Bilan'!I44 -> 0 | L38: ='B. Bilan'!K44-'B. Bilan'!J44 -> 0 | M38: ='B. Bilan'!L44-'B. Bilan'!K44 -> 0
B39: - Dividende | C39: =-('B. Bilan'!C45+'B. Bilan'!C46)+'B. Bilan'!D45 -> 0 | E39: =-('B. Bilan'!D45+'B. Bilan'!D46)+'B. Bilan'!E45 -> 0 | G39: =-('B. Bilan'!E45+'B. Bilan'!E46)+'B. Bilan'!F45 -> 0 | I39: ='B. Bilan'!H45-'A. Comptes de résultats'!I34-('B. Bilan'!F45+'B. Bilan'!F46) -> 0 | J39: ='B. Bilan'!I45-'A. Comptes de résultats'!J34-'B. Bilan'!H45 -> 0 | K39: ='B. Bilan'!J45-'A. Comptes de résultats'!K34-'B. Bilan'!I45 -> 0 | L39: ='B. Bilan'!K45-'A. Comptes de résultats'!L34-'B. Bilan'!J45 -> 0 | M39: ='B. Bilan'!L45-'A. Comptes de résultats'!M34-'B. Bilan'!K45 -> 0
B40: Cash flow des activités financières | C40: =SUM(C29:C39) -> 0 | E40: =SUM(E29:E39) -> 0 | G40: =SUM(G29:G39) -> 0 | I40: =SUM(I29:I39) -> 0 | J40: =SUM(J29:J39) -> 0 | K40: =SUM(K29:K39) -> 0 | L40: =SUM(L29:L39) -> 0 | M40: =SUM(M29:M39) -> 0
B41: Changement des liquidités | C41: =C28+C40 -> 0 | E41: =E28+E40 -> 0 | G41: =G28+G40 -> 0 | I41: =I28+I40 -> 0 | J41: =J28+J40 -> 0 | K41: =K28+K40 -> 0 | L41: =L28+L40 -> 0 | M41: =M28+M40 -> 0
B43: check = 0 | C43: =('B. Bilan'!D8-'B. Bilan'!C8)-C41 -> 0 | E43: =('B. Bilan'!E8-'B. Bilan'!D8)-E41 -> 0 | G43: =('B. Bilan'!F8-'B. Bilan'!E8)-G41 -> 0 | I43: =('B. Bilan'!H8-'B. Bilan'!F8)-I41 -> 0 | J43: =('B. Bilan'!I8-'B. Bilan'!H8)-J41 -> 0 | K43: =('B. Bilan'!J8-'B. Bilan'!I8)-K41 -> 0 | L43: =('B. Bilan'!K8-'B. Bilan'!J8)-L41 -> 0 | M43: =('B. Bilan'!L8-'B. Bilan'!K8)-M41 -> 0

Sheet E. Ratios
B2: Nom de la société | D2: ='A. Comptes de résultats'!D2 -> 0
B3: Date du dernier Exercice [tt.mm.jjjj] | D3: ='A. Comptes de résultats'!D3 -> 44561
B5: Ratios
B6: Position | D6: Effectif-Année | I6: Prévisionnel-Année
D7: =DATE(YEAR(E7)-1,MONTH(E7),DAY(E7)) -> 43465 | E7: =DATE(YEAR(F7)-1,MONTH(F7),DAY(F7)) -> 43830 | F7: =DATE(YEAR(G7)-1,MONTH(G7),DAY(G7)) -> 44196 | G7: =D3 -> 44561 | I7: ='A. Comptes de résultats'!I7 -> 44926 | J7: ='A. Comptes de résultats'!J7 -> 45291 | K7: ='A. Comptes de résultats'!K7 -> 45657 | L7: ='A. Comptes de résultats'!L7 -> 46022 | M7: ='A. Comptes de résultats'!M7 -> 46387
B8: Liquidités
B9: Degré de liquidité I | D9: ='B. Bilan'!C8/'B. Bilan'!C32 -> #DIV/0! | E9: ='B. Bilan'!D8/'B. Bilan'!D32 -> #DIV/0! | F9: ='B. Bilan'!E8/'B. Bilan'!E32 -> #DIV/0! | G9: ='B. Bilan'!F8/'B. Bilan'!F32 -> #DIV/0! | I9: ='B. Bilan'!H8/'B. Bilan'!H32 -> #DIV/0! | J9: ='B. Bilan'!I8/'B. Bilan'!I32 -> #DIV/0! | K9: ='B. Bilan'!J8/'B. Bilan'!J32 -> #DIV/0! | L9: ='B. Bilan'!K8/'B. Bilan'!K32 -> #DIV/0! | M9: ='B. Bilan'!L8/'B. Bilan'!L32 -> #DIV/0!
B10: Degré de liquidité II | D10: =('B. Bilan'!C8+'B. Bilan'!C11+'B. Bilan'!C12)/'B. Bilan'!C32 -> #DIV/0! | E10: =('B. Bilan'!D8+'B. Bilan'!D11+'B. Bilan'!D12)/'B. Bilan'!D32 -> #DIV/0! | F10: =('B. Bilan'!E8+'B. Bilan'!E11+'B. Bilan'!E12)/'B. Bilan'!E32 -> #DIV/0! | G10: =('B. Bilan'!F8+'B. Bilan'!F11+'B. Bilan'!F12)/'B. Bilan'!F32 -> #DIV/0! | I10: =('B. Bilan'!H8+'B. Bilan'!H11+'B. Bilan'!H12)/'B. Bilan'!H32 -> #DIV/0! | J10: =('B. Bilan'!I8+'B. Bilan'!I11+'B. Bilan'!I12)/'B. Bilan'!I32 -> #DIV/0! | K10: =('B. Bilan'!J8+'B. Bilan'!J11+'B. Bilan'!J12)/'B. Bilan'!J32 -> #DIV/0! | L10: =('B. Bilan'!K8+'B. Bilan'!K11+'B. Bilan'!K12)/'B. Bilan'!K32 -> #DIV/0! | M10: =('B. Bilan'!L8+'B. Bilan'!L11+'B. Bilan'!L12)/'B. Bilan'!L32 -> #DIV/0!
B11: Degré de liquidité III | D11: =('B. Bilan'!C8+'B. Bilan'!C11+'B. Bilan'!C12+'B. Bilan'!C13)/'B. Bilan'!C32 -> #DIV/0! | E11: =('B. Bilan'!D8+'B. Bilan'!D11+'B. Bilan'!D12+'B. Bilan'!D13)/'B. Bilan'!D32 -> #DIV/0! | F11: =('B. Bilan'!E8+'B. Bilan'!E11+'B. Bilan'!E12+'B. Bilan'!E13)/'B. Bilan'!E32 -> #DIV/0! | G11: =('B. Bilan'!F8+'B. Bilan'!F11+'B. Bilan'!F12+'B. Bilan'!F13)/'B. Bilan'!F32 -> #DIV/0! | I11: =('B. Bilan'!H8+'B. Bilan'!H11+'B. Bilan'!H12+'B. Bilan'!H13)/'B. Bilan'!H32 -> #DIV/0! | J11: =('B. Bilan'!I8+'B. Bilan'!I11+'B. Bilan'!I12+'B. Bilan'!I13)/'B. Bilan'!I32 -> #DIV/0! | K11: =('B. Bilan'!J8+'B. Bilan'!J11+'B. Bilan'!J12+'B. Bilan'!J13)/'B. Bilan'!J32 -> #DIV/0! | L11: =('B. Bilan'!K8+'B. Bilan'!K11+'B. Bilan'!K12+'B. Bilan'!K13)/'B. Bilan'!K32 -> #DIV/0! | M11: =('B. Bilan'!L8+'B. Bilan'!L11+'B. Bilan'!L12+'B. Bilan'!L13)/'B. Bilan'!L32 -> #DIV/0!
B12: Profitabilité
B13: Marge Résultat brut | D13: ='A. Comptes de résultats'!D11 -> #DIV/0! | E13: ='A. Comptes de résultats'!E11 -> #DIV/0! | F13: ='A. Comptes de résultats'!F11 -> #DIV/0! | G13: ='A. Comptes de résultats'!G11 -> #DIV/0! | I13: ='A. Comptes de résultats'!I11 -> #DIV/0! | J13: ='A. Comptes de résultats'!J11 -> #DIV/0! | K13: ='A. Comptes de résultats'!K11 -> #DIV/0! | L13: ='A. Comptes de résultats'!L11 -> #DIV/0! | M13: ='A. Comptes de résultats'!M11 -> #DIV/0!
B14: Marge EBITDA | D14: ='A. Comptes de résultats'!D23 -> #DIV/0! | E14: ='A. Comptes de résultats'!E23 -> #DIV/0! | F14: ='A. Comptes de résultats'!F23 -> #DIV/0! | G14: ='A. Comptes de résultats'!G23 -> #DIV/0! | I14: ='A. Comptes de résultats'!I23 -> #DIV/0! | J14: ='A. Comptes de résultats'!J23 -> #DIV/0! | K14: ='A. Comptes de résultats'!K23 -> #DIV/0! | L14: ='A. Comptes de résultats'!L23 -> #DIV/0! | M14: ='A. Comptes de résultats'!M23 -> #DIV/0!
B15: Rentabilité
B16: Rentabilité des fonds propres | D16: ='B. Bilan'!C46/'B. Bilan'!C48 -> #DIV/0! | E16: ='B. Bilan'!D46/'B. Bilan'!D48 -> #DIV/0! | F16: ='B. Bilan'!E46/'B. Bilan'!E48 -> #DIV/0! | G16: ='B. Bilan'!F46/'B. Bilan'!F48 -> #DIV/0! | I16: ='B. Bilan'!H46/'B. Bilan'!H48 -> #DIV/0! | J16: ='B. Bilan'!I46/'B. Bilan'!I48 -> #DIV/0! | K16: ='B. Bilan'!J46/'B. Bilan'!J48 -> #DIV/0! | L16: ='B. Bilan'!K46/'B. Bilan'!K48 -> #DIV/0! | M16: ='B. Bilan'!L46/'B. Bilan'!L48 -> #DIV/0!
B17: Rentabilité p/r à la somme du bilan | D17: =('A. Comptes de résultats'!D26+'A. Comptes de résultats'!D32)/'B. Bilan'!C51 -> #DIV/0! | E17: =('A. Comptes de résultats'!E26+'A. Comptes de résultats'!E32)/'B. Bilan'!D51 -> #DIV/0! | F17: =('A. Comptes de résultats'!F26+'A. Comptes de résultats'!F32)/'B. Bilan'!E51 -> #DIV/0! | G17: =('A. Comptes de résultats'!G26+'A. Comptes de résultats'!G32)/'B. Bilan'!F51 -> #DIV/0! | I17: =('A. Comptes de résultats'!I26+'A. Comptes de résultats'!I32)/'B. Bilan'!H51 -> #DIV/0! | J17: =('A. Comptes de résultats'!J26+'A. Comptes de résultats'!J32)/'B. Bilan'!I51 -> #DIV/0! | K17: =('A. Comptes de résultats'!K26+'A. Comptes de résultats'!K32)/'B. Bilan'!J51 -> #DIV/0! | L17: =('A. Comptes de résultats'!L26+'A. Comptes de résultats'!L32)/'B. Bilan'!K51 -> #DIV/0! | M17: =('A. Comptes de résultats'!M26+'A. Comptes de résultats'!M32)/'B. Bilan'!L51 -> #DIV/0!
B18: Rentabilité p/r au chiffre d'affaires | D18: ='A. Comptes de résultats'!D34/'A. Comptes de résultats'!D8 -> #DIV/0! | E18: ='A. Comptes de résultats'!E34/'A. Comptes de résultats'!E8 -> #DIV/0! | F18: ='A. Comptes de résultats'!F34/'A. Comptes de résultats'!F8 -> #DIV/0! | G18: ='A. Comptes de résultats'!G34/'A. Comptes de résultats'!G8 -> #DIV/0! | I18: ='A. Comptes de résultats'!I34/'A. Comptes de résultats'!I8 -> #DIV/0! | J18: ='A. Comptes de résultats'!J34/'A. Comptes de résultats'!J8 -> #DIV/0! | K18: ='A. Comptes de résultats'!K34/'A. Comptes de résultats'!K8 -> #DIV/0! | L18: ='A. Comptes de résultats'!L34/'A. Comptes de résultats'!L8 -> #DIV/0! | M18: ='A. Comptes de résultats'!M34/'A. Comptes de résultats'!M8 -> #DIV/0!
B19: Financement
B20: Degré de fonds propres | D20: ='B. Bilan'!C48/'B. Bilan'!C51 -> #DIV/0! | E20: ='B. Bilan'!D48/'B. Bilan'!D51 -> #DIV/0! | F20: ='B. Bilan'!E48/'B. Bilan'!E51 -> #DIV/0! | G20: ='B. Bilan'!F48/'B. Bilan'!F51 -> #DIV/0! | I20: ='B. Bilan'!H48/'B. Bilan'!H51 -> #DIV/0! | J20: ='B. Bilan'!I48/'B. Bilan'!I51 -> #DIV/0! | K20: ='B. Bilan'!J48/'B. Bilan'!J51 -> #DIV/0! | L20: ='B. Bilan'!K48/'B. Bilan'!K51 -> #DIV/0! | M20: ='B. Bilan'!L48/'B. Bilan'!L51 -> #DIV/0!
B21: Ratio Debt/Equity | D21: =('B. Bilan'!C30+'B. Bilan'!C35+'B. Bilan'!C36+'B. Bilan'!C37)/'B. Bilan'!C48 -> #DIV/0! | E21: =('B. Bilan'!D30+'B. Bilan'!D35+'B. Bilan'!D36+'B. Bilan'!D37)/'B. Bilan'!D48 -> #DIV/0! | F21: =('B. Bilan'!E30+'B. Bilan'!E35+'B. Bilan'!E36+'B. Bilan'!E37)/'B. Bilan'!E48 -> #DIV/0! | G21: =('B. Bilan'!F30+'B. Bilan'!F35+'B. Bilan'!F36+'B. Bilan'!F37)/'B. Bilan'!F48 -> #DIV/0! | I21: =('B. Bilan'!H30+'B. Bilan'!H35+'B. Bilan'!H36+'B. Bilan'!H37)/'B. Bilan'!H48 -> #DIV/0! | J21: =('B. Bilan'!I30+'B. Bilan'!I35+'B. Bilan'!I36+'B. Bilan'!I37)/'B. Bilan'!I48 -> #DIV/0! | K21: =('B. Bilan'!J30+'B. Bilan'!J35+'B. Bilan'!J36+'B. Bilan'!J37)/'B. Bilan'!J48 -> #DIV/0! | L21: =('B. Bilan'!K30+'B. Bilan'!K35+'B. Bilan'!K36+'B. Bilan'!K37)/'B. Bilan'!K48 -> #DIV/0! | M21: =('B. Bilan'!L30+'B. Bilan'!L35+'B. Bilan'!L36+'B. Bilan'!L37)/'B. Bilan'!L48 -> #DIV/0!
B22: Degré de couverture des immobil. II | D22: =('B. Bilan'!C48+'B. Bilan'!C39)/'B. Bilan'!C24 -> #DIV/0! | E22: =('B. Bilan'!D48+'B. Bilan'!D39)/'B. Bilan'!D24 -> #DIV/0! | F22: =('B. Bilan'!E48+'B. Bilan'!E39)/'B. Bilan'!E24 -> #DIV/0! | G22: =('B. Bilan'!F48+'B. Bilan'!F39)/'B. Bilan'!F24 -> #DIV/0! | I22: =('B. Bilan'!H48+'B. Bilan'!H39)/'B. Bilan'!H24 -> #DIV/0! | J22: =('B. Bilan'!I48+'B. Bilan'!I39)/'B. Bilan'!I24 -> #DIV/0! | K22: =('B. Bilan'!J48+'B. Bilan'!J39)/'B. Bilan'!J24 -> #DIV/0! | L22: =('B. Bilan'!K48+'B. Bilan'!K39)/'B. Bilan'!K24 -> #DIV/0! | M22: =('B. Bilan'!L48+'B. Bilan'!L39)/'B. Bilan'!L24 -> #DIV/0!
B23: Debt Management
B24: Degré d'endettement - Brutto | D24: =('B. Bilan'!C30+'B. Bilan'!C35+'B. Bilan'!C36+'B. Bilan'!C37)/'A. Comptes de résultats'!D22 -> #DIV/0! | E24: =('B. Bilan'!D30+'B. Bilan'!D35+'B. Bilan'!D36+'B. Bilan'!D37)/'A. Comptes de résultats'!E22 -> #DIV/0! | F24: =('B. Bilan'!E30+'B. Bilan'!E35+'B. Bilan'!E36+'B. Bilan'!E37)/'A. Comptes de résultats'!F22 -> #DIV/0! | G24: =('B. Bilan'!F30+'B. Bilan'!F35+'B. Bilan'!F36+'B. Bilan'!F37)/'A. Comptes de résultats'!G22 -> #DIV/0! | I24: =('B. Bilan'!H30+'B. Bilan'!H35+'B. Bilan'!H36+'B. Bilan'!H37)/'A. Comptes de résultats'!I22 -> #DIV/0! | J24: =('B. Bilan'!I30+'B. Bilan'!I35+'B. Bilan'!I36+'B. Bilan'!I37)/'A. Comptes de résultats'!J22 -> #DIV/0! | K24: =('B. Bilan'!J30+'B. Bilan'!J35+'B. Bilan'!J36+'B. Bilan'!J37)/'A. Comptes de résultats'!K22 -> #DIV/0! | L24: =('B. Bilan'!K30+'B. Bilan'!K35+'B. Bilan'!K36+'B. Bilan'!K37)/'A. Comptes de résultats'!L22 -> #DIV/0! | M24: =('B. Bilan'!L30+'B. Bilan'!L35+'B. Bilan'!L36+'B. Bilan'!L37)/'A. Comptes de résultats'!M22 -> #DIV/0!
B25: Degré d'endettement - Netto | D25: =(('B. Bilan'!C30+'B. Bilan'!C35+'B. Bilan'!C36+'B. Bilan'!C37)-'B. Bilan'!C8)/'A. Comptes de résultats'!D22 -> #DIV/0! | E25: =(('B. Bilan'!D30+'B. Bilan'!D35+'B. Bilan'!D36+'B. Bilan'!D37)-'B. Bilan'!D8)/'A. Comptes de résultats'!E22 -> #DIV/0! | F25: =(('B. Bilan'!E30+'B. Bilan'!E35+'B. Bilan'!E36+'B. Bilan'!E37)-'B. Bilan'!E8)/'A. Comptes de résultats'!F22 -> #DIV/0! | G25: =(('B. Bilan'!F30+'B. Bilan'!F35+'B. Bilan'!F36+'B. Bilan'!F37)-'B. Bilan'!F8)/'A. Comptes de résultats'!G22 -> #DIV/0! | I25: =(('B. Bilan'!H30+'B. Bilan'!H35+'B. Bilan'!H36+'B. Bilan'!H37)-'B. Bilan'!H8)/'A. Comptes de résultats'!I22 -> #DIV/0! | J25: =(('B. Bilan'!I30+'B. Bilan'!I35+'B. Bilan'!I36+'B. Bilan'!I37)-'B. Bilan'!I8)/'A. Comptes de résultats'!J22 -> #DIV/0! | K25: =(('B. Bilan'!J30+'B. Bilan'!J35+'B. Bilan'!J36+'B. Bilan'!J37)-'B. Bilan'!J8)/'A. Comptes de résultats'!K22 -> #DIV/0! | L25: =(('B. Bilan'!K30+'B. Bilan'!K35+'B. Bilan'!K36+'B. Bilan'!K37)-'B. Bilan'!K8)/'A. Comptes de résultats'!L22 -> #DIV/0! | M25: =(('B. Bilan'!L30+'B. Bilan'!L35+'B. Bilan'!L36+'B. Bilan'!L37)-'B. Bilan'!L8)/'A. Comptes de résultats'!M22 -> #DIV/0!
B26: Kapitalbindung
B27: Debitorenfrist | D27: =('B. Bilan'!C11/'A. Comptes de résultats'!D8)*360 -> #DIV/0! | E27: =('B. Bilan'!D11/'A. Comptes de résultats'!E8)*360 -> #DIV/0! | F27: =('B. Bilan'!E11/'A. Comptes de résultats'!F8)*360 -> #DIV/0! | G27: =('B. Bilan'!F11/'A. Comptes de résultats'!G8)*360 -> #DIV/0! | I27: =('B. Bilan'!H11/'A. Comptes de résultats'!I8)*360 -> #DIV/0! | J27: =('B. Bilan'!I11/'A. Comptes de résultats'!J8)*360 -> #DIV/0! | K27: =('B. Bilan'!J11/'A. Comptes de résultats'!K8)*360 -> #DIV/0! | L27: =('B. Bilan'!K11/'A. Comptes de résultats'!L8)*360 -> #DIV/0! | M27: =('B. Bilan'!L11/'A. Comptes de résultats'!M8)*360 -> #DIV/0!
B28: Kreditorenfrist | D28: =('B. Bilan'!C27/-'A. Comptes de résultats'!D9)*360 -> #DIV/0! | E28: =('B. Bilan'!D27/-'A. Comptes de résultats'!E9)*360 -> #DIV/0! | F28: =('B. Bilan'!E27/-'A. Comptes de résultats'!F9)*360 -> #DIV/0! | G28: =('B. Bilan'!F27/-'A. Comptes de résultats'!G9)*360 -> #DIV/0! | I28: =('B. Bilan'!H27/-'A. Comptes de résultats'!I9)*360 -> #DIV/0! | J28: =('B. Bilan'!I27/-'A. Comptes de résultats'!J9)*360 -> #DIV/0! | K28: =('B. Bilan'!J27/-'A. Comptes de résultats'!K9)*360 -> #DIV/0! | L28: =('B. Bilan'!K27/-'A. Comptes de résultats'!L9)*360 -> #DIV/0! | M28: =('B. Bilan'!L27/-'A. Comptes de résultats'!M9)*360 -> #DIV/0!
B29: Lagerdauer | D29: =('B. Bilan'!C13/-'A. Comptes de résultats'!D9)*360 -> #DIV/0! | E29: =('B. Bilan'!D13/-'A. Comptes de résultats'!E9)*360 -> #DIV/0! | F29: =('B. Bilan'!E13/-'A. Comptes de résultats'!F9)*360 -> #DIV/0! | G29: =('B. Bilan'!F13/-'A. Comptes de résultats'!G9)*360 -> #DIV/0! | I29: =('B. Bilan'!H13/-'A. Comptes de résultats'!I9)*360 -> #DIV/0! | J29: =('B. Bilan'!I13/-'A. Comptes de résultats'!J9)*360 -> #DIV/0! | K29: =('B. Bilan'!J13/-'A. Comptes de résultats'!K9)*360 -> #DIV/0! | L29: =('B. Bilan'!K13/-'A. Comptes de résultats'!L9)*360 -> #DIV/0! | M29: =('B. Bilan'!L13/-'A. Comptes de résultats'!M9)*360 -> #DIV/0!
